Workbook

Sheet راهنمای نسخه v39
A1: نتیجه بررسی v39
A2: فایل مبنا v38 دست نخورده است. این نسخه تکمیل محاسبات است، نه ادعای تکمیل همه اسناد.
A3: موضوع | B3: نتیجه | C3: توضیح | D3: منبع یا روش
A4: وضعیت اجرا | B4: محاسبات تکمیل؛ اسناد ناقص | C4: CR1A بازسازی محاسباتی شد و خروجی ها همگام شدند. سه پرونده سندی هنوز باز هستند. | D4: Gap Review v39
A5: پوشش عددی تغییر رئیس | B5: ='CR1A v39'!B38&" از "&'CR1A v39'!B44 -> 27 از 30 | C5: شامل همه کدهای موجود صفر و یک، حتی فملی که تعارض باز دارد. | D5: CR1A v39؛ ستون C
A6: پوشش محافظه کارانه | B6: ='CR1A v39'!B39&" از "&'CR1A v39'!B44 -> 26 از 30 | C6: بدون تعارض باز ثبت شده؛ تایید مستقل جدید همه منابع نیست. این عدد به جدول استاد منتقل شده است. | D6: CR1A v39؛ ستون F
A7: موارد خارج از مجموعه محافظه کارانه | B7: فملی، رمپنا، وپاسار، حکشتی | C7: فملی متعارض است؛ سه شرکت دیگر نامشخص هستند. هیچ کدام صفرگذاری نشده اند. | D7: CR1A v39؛ ستون های D و M
A8: وتجارت | B8: نیازمند سند خروج | C8: مقدار قبلی ۲۰ درصد با پرچم بررسی حفظ شد. تفاوت فهرست فارسی و انگلیسی بانک تاریخ خروج را مشخص نمی کند. | D8: V39S01؛ V39S02؛ Gap Review v39
A9: وپاسار | B9: گزارش 1526305 سرنخ تازه | C9: فراداده گزارش کنترل های داخلی دوره ۱۴۰۴ پیدا شد؛ متن گزارش و فهرست اعضا دریافت نشد. | D9: V39S04؛ target_filings.json
A10: حکشتی | B10: دو نام تاریخی؛ ترکیب ناقص | C10: فهرست انجمن نام مدیرعامل و رئیس را دارد اما نمایندگان پنج کرسی را در دو نقطه تعیین نمی کند. | D10: V39S05
A11: تغییر داده خام | B11: هیچ مقدار خام گردش تغییر نکرد | C11: ورودی های عددی و ستون تغییر رئیس در Turnover نهایی عینا حفظ شدند؛ اصلاحات در محاسبات، کنترل ها، پوشش و یادداشت ها است. | D11: Changes v39 و کنترل مقایسه خودکار
A12: حساسیت جم | B12: تاریخ موثر در برابر انتشار | C12: کد اصلی تغییر رئیس یک است؛ مبنای انتشار طبق یادداشت v38 می تواند آن را صفر کند. این تفاوت در مدل تجربی باید صریح باشد. | D12: CR1A v39؛ ردیف جم
A13: جهت CR1A | B13: کنترلی؛ خارج شاخص ترکیبی | C13: تغییر رئیس به صورت پیش فرض خوب یا بد تفسیر نمی شود. | D13: جدول استاد؛ معماری به روز شده
A14: فرمول های ورودی تاریخی | B14: محافظ عددی و هشدار صریح | C14: ۳۶ فرمول Audit Coverage بر عنوان متنی تقسیم یا تفریق می کردند. محاسبه نامعتبر تا بازیابی عدد تاریخی خالی است و پرچم دارد. | D14: Audit Coverage ستون M؛ Changes v39
A15: بازمحاسبه فایل | B15: محاسبه و ذخیره نتیجه انجام شد | C15: همه فرمول ها بازمحاسبه و مقادیر محاسبه شده در فایل ذخیره شد؛ خطای محاسباتی باقی مانده صفر است. پنج نرخ اصلی نیز مستقل از موتور محاسبات کنترل شدند. | D15: QA v39
A16: سابقه ممیزی | B16: حفظ شده | C16: برگه های ممیزی قدیمی تاریخچه پروژه اند. به جز سلول های ثبت شده در Changes v39، ادعای به روز شدن کامل آن برگه ها نداریم. | D16: Changes v39
A17: محدودیت دسترسی | B17: متن اسناد جدید کدال دریافت نشد | C17: خطای دسترسی به معنی نبود یا منتشر نشدن سند نیست. فقط متن جستجو و فراداده در دسترس استفاده شد. | D17: Sources v39؛ fetch_log.json

Sheet Gap Review v39
A1: نتیجه چهار کار در v39
A2: تکمیل محاسبات انجام شد؛ سه پرونده سندی هنوز بسته نشده اند. هیچ داده خام حدسی وارد نشده است.
A3: موضوع | B3: نتیجه | C3: یافته تازه یا کنترل انجام شده | D3: اثر بر داده | E3: چرا هنوز محدودیت دارد | F3: سند لازم یا مسیر بعدی | G3: منابع
A4: CR1A | B4: بازمحاسبه انجام شد | C4: ۳۰ ردیف کنترل شد؛ ۲۷ کد موجود، ۲۶ مورد بدون تعارض باز ثبت شده، سه نامشخص و یک تعارض فملی. هویت رئیس برای هشت شرکت از بازسازی v38 تطبیق داده شد. | D4: جدول استاد، معماری و برگه های وابسته با پوشش محافظه کارانه همگام شدند. | E4: ۲۶ مورد به معنی بازخوانی مستقل همه اسناد در v39 نیست. حساسیت تاریخ انتشار جم حفظ شد. | F4: بستن تعارض فملی و تکمیل هویت رئیس در رمپنا، وپاسار و حکشتی؛ این موارد صفر نیستند. | G4: CR1A v39؛ V39S10
A5: وتجارت | B5: حل جزئی؛ سند خروج پیدا نشد | C5: نسخه فارسی رسمی چهار نام و نسخه انگلیسی پنج نام شامل شریفیان دارد. این اختلاف ثبت شد. | D5: گردش فردی ۱ از ۵ بدون تغییر و با برچسب نیازمند بررسی باقی ماند؛ تغییر رئیس صفر با محدودیت قبلی. | E5: صفحات بدون تاریخ موثر سند خروج نیستند؛ تعارض نسخه اولیه و اصلاحیه در v38 هنوز نیازمند سند است. | F5: صورتجلسه خروج یا اعلام رسمی تاریخ پایان عضویت شریفیان و تطبیق با اصلاحیه 1444154. | G5: V39S01، V39S02، V39S03، V39S06
A6: وپاسار | B6: حل نشد؛ سرنخ تازه ثبت شد | C6: در فهرست پروژه گزارش کنترل های داخلی پایان ۱۴۰۴ با ردیابی 1526305 و انتشار ۱۴۰۵/۰۲/۲۷ پیدا شد. | D6: هیچ نام یا مقدار گردش از فراداده استخراج نشد؛ داده ۱۴۰۴ همچنان نامشخص است. | E6: متن گزارش و نام امضاکنندگان دریافت نشد. اختلاف پایه هفت نفره با پنج نفره نیز حل نشده است. | F6: دریافت گزارش 1526305 و بررسی امضاها در کنار گزارش فعالیت، صورتجلسه و تاریخ موثر عضویت؛ یک فهرست فعلی کافی نیست. | G6: V39S04، V39S08، V39S09
A7: حکشتی | B7: حل نشد؛ شناسایی تاریخی محدود | C7: فهرست انجمن در ۱۴۰۳/۱۰/۱۷ نام مدرس خیابانی به عنوان مدیرعامل و علی مسیبی بهروز به عنوان رئیس را دارد. | D7: هیچ نماینده ای به کرسی حقوقی منتسب نشد؛ گردش فردی و تغییر رئیس همچنان نامشخص هستند. | E7: دو نام تاریخی جایگزین پنج نماینده در دو نقطه مشترک نیست و منبع، صفحه رسمی خود ناشر نیست. | F7: صورتجلسه تعیین سمت یا صفحه رسمی تاریخ دار همراه با تطبیق هر نماینده با شخص حقوقی در دو نقطه. | G7: V39S05، V39S07، V39S09

Sheet CR1A v39
A1: بازمحاسبه و تفکیک وضعیت CR1A
A2: پنجره مشترک ۱۴۰۳/۱۲/۲۹ تا ۱۴۰۴/۱۲/۲۹؛ پوشش عددی با کفایت شواهد یکسان نیست. مقادیر قبلی بدون سند تازه تغییر نکرده اند.
A3: شرکت | B3: ورودی متنی v38 | C3: کد عددی موجود | D3: وضعیت شواهد | E3: ورود به شمارش محافظه کارانه | F3: کد قابل استفاده با محدودیت | G3: رئیس در مبنا | H3: رئیس در پایان | I3: روش بررسی | J3: ارجاع و ردیابی | K3: نشانی منابع | L3: حساسیت تاریخ انتشار | M3: دلیل فقدان یا تعارض | N3: یادداشت | O3: کنترل یکتایی
A4: فملی | B4: ='Turnover نهایی'!V4 -> خیر | C4: =IF(B4="بله",1,IF(B4="خیر",0,"")) -> 0 | D4: NEEDS_REVIEW | E4: خیر | F4: =IF(AND(E4="بله",ISNUMBER(C4)),C4,"") | I4: حفظ پرچم تعارض قبلی؛ بدون حدس درباره نام رئیس یا جهت تغییر. | J4: Iran_BSI_v33_Phase4_2K_FinalTurnoverClosure.xlsx | برگه های گردش اشخاص حقیقی، تغییر نماینده، تغییر شخص حقوقی، اعضای جدید، ثبات هیئت و تغییر رئیس | K4: برای ردیابی پایه به فایل v33 و Source_IDهای همان فاز مراجعه شود | M4: COULD_NOT_VERIFY | N4: تعارض تاریخی CR1A در Conflict Log C04 و Audit فرمول ها باقی است. v38 این شرکت را بازسازی نکرده؛ مقدار خام خیر حفظ شد اما از پوشش محافظه کارانه کنار گذاشته شد. | O4: =IF(COUNTIF($A$4:A4,A4)=1,1,0) -> 1
A5: تاپیکو | B5: ='Turnover نهایی'!V5 -> بله | C5: =IF(B5="بله",1,IF(B5="خیر",0,"")) -> 1 | D5: V38_CONFIRMED | E5: بله | F5: =IF(AND(E5="بله",ISNUMBER(C5)),C5,"") -> 1 | G5: جعفر ربیعی | H5: محمدمهدی رحمتی | I5: مقایسه هویت رئیس در دو نقطه از بازسازی سطح کرسی v38؛ عدم تغییر سایر سمت ها ملاک نیست. | J5: Turnover Seat Reconstruction؛ 1311653 / 1477918 | K5: https://www.codal.ir/Reports/Decision.aspx?LetterSerial=QijK3OnJnjtoOOObOOOYV1GqeqyQ%3d%3d&rt=2&let=19&ct=0&ft=-1 https://www.codal.ir/Reports/Decision.aspx?LetterSerial=Exef5qCkFaU4GYSKSR3wjg%3d%3d&rt=2&let=19&ct=0&ft=-1 | N5: مبنای این مرحله شواهد مستند در فایل v38 است؛ دریافت مجدد مستقل اسناد کدال در این محیط ممکن نشد. | O5: =IF(COUNTIF($A$4:A5,A5)=1,1,0) -> 1
A6: فارس | B6: ='Turnover نهایی'!V6 -> بله | C6: =IF(B6="بله",1,IF(B6="خیر",0,"")) -> 1 | D6: INHERITED_WITH_LIMITATION | E6: بله | F6: =IF(AND(E6="بله",ISNUMBER(C6)),C6,"") -> 1 | I6: انتقال کنترل شده مقدار v38؛ تایید مجدد مستقل همه منابع این شرکت در v39 انجام نشده است. | J6: Iran_BSI_v33_Phase4_2K_FinalTurnoverClosure.xlsx | برگه های گردش اشخاص حقیقی، تغییر نماینده، تغییر شخص حقوقی، اعضای جدید، ثبات هیئت و تغییر رئیس | تایید تکمیلی در Iran_BSI_v31_Phase4_2I_MaximumMeasureRecovery.xlsx، شواهد خام | K6: برای ردیابی پایه به فایل v33 و Source_IDهای همان فاز مراجعه شود | N6: پذیرش به معنی نبود تعارض باز ثبت شده در فایل است؛ نه تایید مستقل کامل اسناد اولیه. | O6: =IF(COUNTIF($A$4:A6,A6)=1,1,0) -> 1
A7: خودرو | B7: ='Turnover نهایی'!V7 -> خیر | C7: =IF(B7="بله",1,IF(B7="خیر",0,"")) -> 0 | D7: V38_CONFIRMED | E7: بله | F7: =IF(AND(E7="بله",ISNUMBER(C7)),C7,"") -> 0 | G7: یوسف الهی شکیب | H7: یوسف الهی شکیب | I7: مقایسه هویت رئیس در دو نقطه از بازسازی سطح کرسی v38؛ عدم تغییر سایر سمت ها ملاک نیست. | J7: Turnover Seat Reconstruction؛ 1306740 / 1417850 | K7: https://www.codal.ir/Reports/Decision.aspx?LetterSerial=gVTCoHYs1M0v5mNrsaCDkA%3d%3d&rt=0&let=19&ct=0&ft=-1 https://www.codal.ir/Reports/Decision.aspx?LetterSerial=8qXiOOObOOOscQQQaQQQfIOkx3DWj8Uw1Q%3d%3d&rt=0&let=19&ct=0&ft=-1 | N7: مبنای این مرحله شواهد مستند در فایل v38 است؛ دریافت مجدد مستقل اسناد کدال در این محیط ممکن نشد. | O7: =IF(COUNTIF($A$4:A7,A7)=1,1,0) -> 1
A8: زاگرس | B8: ='Turnover نهایی'!V8 -> بله | C8: =IF(B8="بله",1,IF(B8="خیر",0,"")) -> 1 | D8: INHERITED_WITH_LIMITATION | E8: بله | F8: =IF(AND(E8="بله",ISNUMBER(C8)),C8,"") -> 1 | I8: انتقال کنترل شده مقدار v38؛ تایید مجدد مستقل همه منابع این شرکت در v39 انجام نشده است. | J8: SRC_ZGRS_1404_002 (p.26, FY1403) و SRC_ZGRS_1404_001 (p.26, FY1404) | بازخوانی کامل این فاز؛ بدون دانلود جدید Iran_BSI_v33_Phase4_2K_FinalTurnoverClosure.xlsx | تطبیق کرسی ها و شواهد خام | SRC_ZGRS_1404_002 و SRC_ZGRS_1404_001، صفحه ۲۶ | K8: برای ردیابی پایه به فایل v33 و Source_IDهای همان فاز مراجعه شود | N8: پذیرش به معنی نبود تعارض باز ثبت شده در فایل است؛ نه تایید مستقل کامل اسناد اولیه. | O8: =IF(COUNTIF($A$4:A8,A8)=1,1,0) -> 1
A9: شبندر | B9: ='Turnover نهایی'!V9 -> بله | C9: =IF(B9="بله",1,IF(B9="خیر",0,"")) -> 1 | D9: INHERITED_WITH_LIMITATION | E9: بله | F9: =IF(AND(E9="بله",ISNUMBER(C9)),C9,"") -> 1 | I9: انتقال کنترل شده مقدار v38؛ تایید مجدد مستقل همه منابع این شرکت در v39 انجام نشده است. | J9: SRC_SHBN_1404_007 | T19 اصلاحیه | جلسه هیئت مدیره ۱۴۰۳/۱۲/۲۷ | صفحه ۱ | Roster مستقیم ۱۴۰۳ SRC_SHBN_1404_003 | T19 | جلسه هیئت مدیره ۱۴۰۴/۱۰/۱۸ | صفحه ۱ | Roster مستقیم ۱۴۰۴ SRC_SHBN_1404_001 (p.55 56 کمیته حسابرسی، p.82 84 روستر هیئت‌مدیره) | بازخوانی جزئی این فاز با الگوی جستجوی عربی؛ بدون دانلود جدید | K9: https://www.codal.ir/Reports/Decision.aspx?LetterSerial=ULk65ZOHpAkFOOObOOOb3pLpblJQ%3d%3d&rt=0&let=19&ct=0&ft=-1 https://www.codal.ir/Reports/Decision.aspx?LetterSerial=kealwqnfPYdWwbR3UB9uZw%3d%3d&rt=0&let=19&ct=0&ft=-1 | N9: پذیرش به معنی نبود تعارض باز ثبت شده در فایل است؛ نه تایید مستقل کامل اسناد اولیه. | O9: =IF(COUNTIF($A$4:A9,A9)=1,1,0) -> 1
A10: پارس | B10: ='Turnover نهایی'!V10 -> بله | C10: =IF(B10="بله",1,IF(B10="خیر",0,"")) -> 1 | D10: INHERITED_WITH_LIMITATION | E10: بله | F10: =IF(AND(E10="بله",ISNUMBER(C10)),C10,"") -> 1 | I10: انتقال کنترل شده مقدار v38؛ تایید مجدد مستقل همه منابع این شرکت در v39 انجام نشده است. | J10: SRC_PARS_1404_008 | T19 | جلسه هیئت مدیره ۱۴۰۴/۰۱/۳۰ | صفحه ۱ | ستون نماینده قبلی برای بازسازی وضعیت نزدیک پایان ۱۴۰۳ SRC_PARS_1404_005 | T19 | جلسه هیئت مدیره ۱۴۰۴/۰۷/۲۶ | صفحه ۱ | آخرین Snapshot تاییدشده پیش از Cutoff ۱۴۰۴ در آرشیو | K10: https://www.codal.ir/Reports/Decision.aspx?LetterSerial=sjHofZygVLXICVj8iXL3Aw%3d%3d&rt=0&let=19&ct=0&ft=-1 https://www.codal.ir/Reports/Decision.aspx?LetterSerial=1kqm2T6e5zV5EQQQaQQQKdlIj9HA%3d%3d&rt=0&let=19&ct=0&ft=-1 | N10: پذیرش به معنی نبود تعارض باز ثبت شده در فایل است؛ نه تایید مستقل کامل اسناد اولیه. | O10: =IF(COUNTIF($A$4:A10,A10)=1,1,0) -> 1
A11: شتران | B11: ='Turnover نهایی'!V11 -> خیر | C11: =IF(B11="بله",1,IF(B11="خیر",0,"")) -> 0 | D11: INHERITED_WITH_LIMITATION | E11: بله | F11: =IF(AND(E11="بله",ISNUMBER(C11)),C11,"") -> 0 | I11: انتقال کنترل شده مقدار v38؛ تایید مجدد مستقل همه منابع این شرکت در v39 انجام نشده است. | J11: SRC_SHTR_1403_001 | گزارش فعالیت هیئت مدیره | دوره منتهی به ۱۴۰۳/۱۲/۳۰ | PDF صفحه ۱۶، چاپی ۱۴ | Roster مستقیم ۱۴۰۳ SRC_SHTR_1404_002 | گزارش فعالیت هیئت مدیره | دوره منتهی به ۱۴۰۴/۱۲/۲۹ | PDF صفحه ۱۷، چاپی ۱۵ | Roster مستقیم ۱۴۰۴ | K11: https://www.codal.ir/Reports/Attachment.aspx?LetterSerial=W3P2HVjIaDXFbdMemqSeUA%3d%3d https://www.codal.ir/Reports/Attachment.aspx?LetterSerial=F0veQQQaQQQX4tai7nAftHYyrDhg%3d%3d | N11: پذیرش به معنی نبود تعارض باز ثبت شده در فایل است؛ نه تایید مستقل کامل اسناد اولیه. | O11: =IF(COUNTIF($A$4:A11,A11)=1,1,0) -> 1
A12: وتجارت | B12: ='Turnover نهایی'!V12 -> خیر | C12: =IF(B12="بله",1,IF(B12="خیر",0,"")) -> 0 | D12: CHAIR_WITH_LIMITATION | E12: بله | F12: =IF(AND(E12="بله",ISNUMBER(C12)),C12,"") -> 0 | G12: مرتضی ترک‌تبریزی | H12: مرتضی ترک‌تبریزی | I12: مقایسه هویت رئیس در دو نقطه از بازسازی سطح کرسی v38؛ عدم تغییر سایر سمت ها ملاک نیست. | J12: Turnover Seat Reconstruction؛ 1159936 / 1444154 | K12: https://www.codal.ir/Reports/Decision.aspx?LetterSerial=OqEx%2bg3X3xQQQaQQQ1V8FTa1bU9w%3d%3d&rt=3&let=19&ct=0&ft=-1 https://www.codal.ir/Reports/Decision.aspx?LetterSerial=tL1npzfj3XSDR4oEqs1VIw%3d%3d&rt=3&let=19&ct=0&ft=-1 | N12: نام ترک تبریزی در هر دو نقطه بازسازی v38 یکسان است؛ ابهام تاریخ خروج شریفیان به صورت مستقل در گردش افراد باقی است. صفحات فارسی و انگلیسی بانک متفاوت اند. | O12: =IF(COUNTIF($A$4:A12,A12)=1,1,0) -> 1
A13: رمپنا | B13: ='Turnover نهایی'!V13 -> نامشخص | C13: =IF(B13="بله",1,IF(B13="خیر",0,"")) | D13: MISSING | E13: خیر | F13: =IF(AND(E13="بله",ISNUMBER(C13)),C13,"") | I13: انتقال کنترل شده مقدار v38؛ تایید مجدد مستقل همه منابع این شرکت در v39 انجام نشده است. | J13: SRC_RMPN_1404_011 | افشای نوع ۱۹، جلسه هیئت مدیره ۱۴۰۴/۰۲/۲۱ | بازسازی ۱۴۰۳ | صفحه ۱ | ستون نماینده قبلی برای بازسازی Cutoff ۱۴۰۳ استفاده شد SRC_RMPN_1404_008 | افشای نوع ۱۹، جلسه هیئت مدیره ۱۴۰۴/۱۰/۲۸ | ۱۴۰۴ | صفحات ۱ و ۲ | آخرین افشای نوع ۱۹ موجود پیش از Cutoff ۱۴۰۴/۱۲/۲۹ | K13: https://www.codal.ir/Reports/Decision.aspx?LetterSerial=gsard4xmaj4Zi8yOS8AWMA%3d%3d&rt=5&let=19&ct=0&ft=-1 https://www.codal.ir/Reports/Decision.aspx?LetterSerial=4P4QQQaQQQssbMX9ZMuZVciqBKOOObOOOg%3d%3d&rt=5&let=19&ct=0&ft=-1 | M13: INSUFFICIENT_EVIDENCE | N13: داده نامشخص به صفر تبدیل نشد. | O13: =IF(COUNTIF($A$4:A13,A13)=1,1,0) -> 1
A14: فخوز | B14: ='Turnover نهایی'!V14 -> بله | C14: =IF(B14="بله",1,IF(B14="خیر",0,"")) -> 1 | D14: INHERITED_WITH_LIMITATION | E14: بله | F14: =IF(AND(E14="بله",ISNUMBER(C14)),C14,"") -> 1 | I14: انتقال کنترل شده مقدار v38؛ تایید مجدد مستقل همه منابع این شرکت در v39 انجام نشده است. | J14: SRC_FKHZ_1404_002 | گزارش فعالیت هیئت مدیره منتهی به ۱۴۰۳/۱۲/۳۰ | ۱۴۰۳ | صفحه ۳۴ | روستر کامل ۱۴۰۳ SRC_FKHZ_1404_004 | افشای نوع ۱۹، جلسه هیئت مدیره ۱۴۰۴/۰۵/۲۷ | ۱۴۰۴ | صفحه ۱ | آخرین افشای نوع ۱۹ پیش از Cutoff | K14: برای ردیابی پایه به فایل v33 و Source_IDهای همان فاز مراجعه شود | N14: پذیرش به معنی نبود تعارض باز ثبت شده در فایل است؛ نه تایید مستقل کامل اسناد اولیه. | O14: =IF(COUNTIF($A$4:A14,A14)=1,1,0) -> 1
A15: شستا | B15: ='Turnover نهایی'!V15 -> بله | C15: =IF(B15="بله",1,IF(B15="خیر",0,"")) -> 1 | D15: INHERITED_WITH_LIMITATION | E15: بله | F15: =IF(AND(E15="بله",ISNUMBER(C15)),C15,"") -> 1 | I15: انتقال کنترل شده مقدار v38؛ تایید مجدد مستقل همه منابع این شرکت در v39 انجام نشده است. | J15: SRC_SHST_1404_015 | افشای نوع ۱۹ | ۱۴۰۳ | ۱ | Snapshot مبنا برای ۱۴۰۳ SRC_SHST_1404_007 | افشای نوع ۱۹ | ۱۴۰۴ | ۱ | Snapshot مبنا برای ۱۴۰۴ | K15: https://www.codal.ir/Reports/Decision.aspx?LetterSerial=b8oxHadTuSstqVNc5Bqzjw%3d%3d&rt=2&let=19&ct=0&ft=-1 https://www.codal.ir/Reports/Decision.aspx?LetterSerial=pk2gUF4FVfw9cOOObOOOOR6kSTDg%3d%3d&rt=2&let=19&ct=0&ft=-1 | N15: پذیرش به معنی نبود تعارض باز ثبت شده در فایل است؛ نه تایید مستقل کامل اسناد اولیه. | O15: =IF(COUNTIF($A$4:A15,A15)=1,1,0) -> 1
A16: شپنا | B16: ='Turnover نهایی'!V16 -> خیر | C16: =IF(B16="بله",1,IF(B16="خیر",0,"")) -> 0 | D16: INHERITED_WITH_LIMITATION | E16: بله | F16: =IF(AND(E16="بله",ISNUMBER(C16)),C16,"") -> 0 | I16: انتقال کنترل شده مقدار v38؛ تایید مجدد مستقل همه منابع این شرکت در v39 انجام نشده است. | J16: SRC_SHPN_1404_002 | افشای نوع ۱۹ | ۱۴۰۳ | ۱ | Snapshot مبنا برای ۱۴۰۳ SRC_SHPN_1404_004 | افشای نوع ۱۹ | ۱۴۰۴ | ۱ تا ۲ | Snapshot مبنا برای ۱۴۰۴ | K16: https://www.codal.ir/Reports/Decision.aspx?LetterSerial=BgB1TPEYicGYh74gmrG9mA%3d%3d&rt=0&let=19&ct=0&ft=-1 https://www.codal.ir/Reports/Decision.aspx?LetterSerial=zWRtzdFgEWKY0H4XNrzRzA%3d%3d&rt=0&let=19&ct=0&ft=-1 | N16: پذیرش به معنی نبود تعارض باز ثبت شده در فایل است؛ نه تایید مستقل کامل اسناد اولیه. | O16: =IF(COUNTIF($A$4:A16,A16)=1,1,0) -> 1
A17: وغدیر | B17: ='Turnover نهایی'!V17 -> خیر | C17: =IF(B17="بله",1,IF(B17="خیر",0,"")) -> 0 | D17: INHERITED_WITH_LIMITATION | E17: بله | F17: =IF(AND(E17="بله",ISNUMBER(C17)),C17,"") -> 0 | I17: انتقال کنترل شده مقدار v38؛ تایید مجدد مستقل همه منابع این شرکت در v39 انجام نشده است. | J17: SRC_VGHD_1404_002 | افشای نوع ۱۹ | ۱۴۰۳ | ۱ | Snapshot مبنا برای ۱۴۰۳ SRC_VGHD_1404_006 | افشای نوع ۱۹ | ۱۴۰۴ | ۱ | Snapshot مبنا برای ۱۴۰۴ | K17: https://www.codal.ir/Reports/Decision.aspx?LetterSerial=b9uqvOIQIMvyGYAfsuoWUg%3d%3d&rt=2&let=19&ct=0&ft=-1 https://www.codal.ir/Reports/Decision.aspx?LetterSerial=ytYjZCpQQQaQQQ34BFQkm8DLxX9A%3d%3d&rt=2&let=19&ct=0&ft=-1 | N17: پذیرش به معنی نبود تعارض باز ثبت شده در فایل است؛ نه تایید مستقل کامل اسناد اولیه. | O17: =IF(COUNTIF($A$4:A17,A17)=1,1,0) -> 1
A18: نوری | B18: ='Turnover نهایی'!V18 -> بله | C18: =IF(B18="بله",1,IF(B18="خیر",0,"")) -> 1 | D18: INHERITED_WITH_LIMITATION | E18: بله | F18: =IF(AND(E18="بله",ISNUMBER(C18)),C18,"") -> 1 | I18: انتقال کنترل شده مقدار v38؛ تایید مجدد مستقل همه منابع این شرکت در v39 انجام نشده است. | J18: SRC_NOURI_1403_001 | گزارش فعالیت هیئت مدیره | ۱۴۰۳ | ۳۹ | Snapshot مبنا برای ۱۴۰۳ SRC_NOOR_1404_007 + SRC_NOOR_1404_005 | گزارش فعالیت هیئت مدیره و Cross Check افشای نوع ۱۹ | ۱۴۰۴ | ۴۱ و افشای نوع ۱۹ صفحه ۱ | Snapshot مبنا برای ۱۴۰۴ | K18: https://www.codal.ir/Reports/Attachment.aspx?LetterSerial=qQQQaQQQXL8Mm5NCUb8eyBSic7hA%3d%3d https://www.codal.ir/Reports/Attachment.aspx?LetterSerial=lWuukNFzDitnWL7VD4weCA%3d%3d | N18: پذیرش به معنی نبود تعارض باز ثبت شده در فایل است؛ نه تایید مستقل کامل اسناد اولیه. | O18: =IF(COUNTIF($A$4:A18,A18)=1,1,0) -> 1
A19: فولاد | B19: ='Turnover نهایی'!V19 -> بله | C19: =IF(B19="بله",1,IF(B19="خیر",0,"")) -> 1 | D19: INHERITED_WITH_LIMITATION | E19: بله | F19: =IF(AND(E19="بله",ISNUMBER(C19)),C19,"") -> 1 | I19: انتقال کنترل شده مقدار v38؛ تایید مجدد مستقل همه منابع این شرکت در v39 انجام نشده است. | J19: SRC_FOLD_1403_001 | گزارش فعالیت هیئت مدیره | ۱۴۰۳ | ۴ | Snapshot مبنا برای ۱۴۰۳ SRC_FOLD_1404_002 | گزارش فعالیت هیئت مدیره | ۱۴۰۴ | ۵ و ۳۱ | Snapshot مبنا برای ۱۴۰۴ و تاریخ انتصاب اعضا | K19: https://www.codal.ir/Reports/Attachment.aspx?LetterSerial=lIOOObOOOFuv6MQlLw20bmBKF3Cw%3d%3d https://www.codal.ir/Reports/Attachment.aspx?LetterSerial=DjTPnm9Pa79X4Gv1Zp8FQQQaQQQQ%3d%3d | N19: پذیرش به معنی نبود تعارض باز ثبت شده در فایل است؛ نه تایید مستقل کامل اسناد اولیه. | O19: =IF(COUNTIF($A$4:A19,A19)=1,1,0) -> 1
A20: کچاد | B20: ='Turnover نهایی'!V20 -> بله | C20: =IF(B20="بله",1,IF(B20="خیر",0,"")) -> 1 | D20: V38_CONFIRMED | E20: بله | F20: =IF(AND(E20="بله",ISNUMBER(C20)),C20,"") -> 1 | G20: محمود صلاحی | H20: محمدرضا تابش | I20: مقایسه هویت رئیس در دو نقطه از بازسازی سطح کرسی v38؛ عدم تغییر سایر سمت ها ملاک نیست. | J20: Turnover Seat Reconstruction؛ 1287746 / 1473973 | K20: https://www.codal.ir/Reports/Decision.aspx?LetterSerial=v9VDr2f0BIJNqKEnWy6Rug%3d%3d&rt=0&let=19&ct=0&ft=-1 https://www.codal.ir/Reports/Decision.aspx?LetterSerial=XPg1kJyBIkadWnCXHnsdKg%3d%3d&rt=0&let=19&ct=0&ft=-1 | N20: مبنای این مرحله شواهد مستند در فایل v38 است؛ دریافت مجدد مستقل اسناد کدال در این محیط ممکن نشد. | O20: =IF(COUNTIF($A$4:A20,A20)=1,1,0) -> 1
A21: کگل | B21: ='Turnover نهایی'!V21 -> بله | C21: =IF(B21="بله",1,IF(B21="خیر",0,"")) -> 1 | D21: INHERITED_WITH_LIMITATION | E21: بله | F21: =IF(AND(E21="بله",ISNUMBER(C21)),C21,"") -> 1 | I21: انتقال کنترل شده مقدار v38؛ تایید مجدد مستقل همه منابع این شرکت در v39 انجام نشده است. | J21: SRC_KGOL_1404_002 | افشای نوع ۱۹ | ۱۴۰۳ | ۱ | Snapshot مبنا برای پایان ۱۴۰۳ و جلوگیری از Look Ahead SRC_KGOL_1404_004 | افشای نوع ۱۹ | ۱۴۰۴ | ۱ | Snapshot مبنا برای ۱۴۰۴ | K21: https://www.codal.ir/Reports/Decision.aspx?LetterSerial=V8TQGa6IRAmh3pwzvDL0KQ%3d%3d&rt=0&let=19&ct=0&ft=-1 https://www.codal.ir/Reports/Decision.aspx?LetterSerial=IYIOOObOOO6mh6t3bHqdV5BigMrg%3d%3d&rt=0&let=19&ct=0&ft=-1 | N21: پذیرش به معنی نبود تعارض باز ثبت شده در فایل است؛ نه تایید مستقل کامل اسناد اولیه. | O21: =IF(COUNTIF($A$4:A21,A21)=1,1,0) -> 1
A22: پارسان | B22: ='Turnover نهایی'!V22 -> خیر | C22: =IF(B22="بله",1,IF(B22="خیر",0,"")) -> 0 | D22: V38_HIGH | E22: بله | F22: =IF(AND(E22="بله",ISNUMBER(C22)),C22,"") -> 0 | G22: احد امیری | H22: احد امیری | I22: مقایسه هویت رئیس در دو نقطه از بازسازی سطح کرسی v38؛ عدم تغییر سایر سمت ها ملاک نیست. | J22: Turnover Seat Reconstruction؛ 1288275 / 1443940 | K22: https://www.codal.ir/Reports/Decision.aspx?LetterSerial=DsOgAmOOObOOOXCBilD6gqB1SIaw%3d%3d&rt=2&let=19&ct=0&ft=-1 https://www.codal.ir/Reports/Decision.aspx?LetterSerial=zNIQQQaQQQIYcl2yMb4DUIPu3s7w%3d%3d&rt=2&let=19&ct=0&ft=-1 | N22: مبنای این مرحله شواهد مستند در فایل v38 است؛ دریافت مجدد مستقل اسناد کدال در این محیط ممکن نشد. | O22: =IF(COUNTIF($A$4:A22,A22)=1,1,0) -> 1
A23: اخابر | B23: ='Turnover نهایی'!V23 -> خیر | C23: =IF(B23="بله",1,IF(B23="خیر",0,"")) -> 0 | D23: INHERITED_WITH_LIMITATION | E23: بله | F23: =IF(AND(E23="بله",ISNUMBER(C23)),C23,"") -> 0 | I23: انتقال کنترل شده مقدار v38؛ تایید مجدد مستقل همه منابع این شرکت در v39 انجام نشده است. | J23: SRC_AKHB_1404_002 | گزارش فعالیت هیئت مدیره | ۱۴۰۳ | ۹۳ تا ۹۴ | Snapshot مبنا برای ۱۴۰۳ SRC_AKHB_1404_003 | افشای نوع ۱۹ | ۱۴۰۴ | ۱ | Snapshot اصلی ۱۴۰۴ و تایید نمایندگان SRC_AKHB_1404_005 | افشای نوع ۱۹ | ۱۴۰۴ | ۱ | کنترل تغییر اشخاص حقوقی در طول سال | K23: https://www.codal.ir/Reports/Attachment.aspx?LetterSerial=l18osNfAAH2DvvstKQQQaQQQYuHQ%3d%3d https://www.codal.ir/Reports/Decision.aspx?LetterSerial=GSIO5iJOn2Ini6eniOOOObOOOopw%3d%3d&rt=5&let=19&ct=0&ft=-1 https://www.codal.ir/Reports/Decision.aspx?LetterSerial=iXcFNxwCjn4aV4ptXi6QQQaQQQjA%3d%3d&rt=5&let=19&ct=0&ft=-1 | N23: پذیرش به معنی نبود تعارض باز ثبت شده در فایل است؛ نه تایید مستقل کامل اسناد اولیه. | O23: =IF(COUNTIF($A$4:A23,A23)=1,1,0) -> 1
A24: جم | B24: ='Turnover نهایی'!V24 -> بله | C24: =IF(B24="بله",1,IF(B24="خیر",0,"")) -> 1 | D24: V38_HIGH | E24: بله | F24: =IF(AND(E24="بله",ISNUMBER(C24)),C24,"") -> 1 | G24: متین دیداری | H24: محمدسجاد سیاهکارزاده | I24: مقایسه هویت رئیس در دو نقطه از بازسازی سطح کرسی v38؛ عدم تغییر سایر سمت ها ملاک نیست. | J24: Turnover Seat Reconstruction؛ 1171265 / 1527389 | K24: https://www.codal.ir/Reports/Decision.aspx?LetterSerial=SZoueUaBHVA%2bs%2bgcP%2bwj4A%3d%3d&rt=0&let=19&ct=0&ft=-1 https://www.codal.ir/Reports/Decision.aspx?LetterSerial=QQQaQQQtpQVpIOOObOOOPhcgQQQaQQQA5ahYjCjA%3d%3d&rt=0&let=19&ct=0&ft=-1 | L24: طبق یادداشت v38 رویداد ۱۴۰۴/۱۲/۲۵ و انتشار ۱۴۰۵/۰۲/۲۹؛ با مبنای تاریخ انتشار تغییر رئیس می تواند صفر شود. کد اصلی این فایل مبتنی بر تاریخ موثر است. | N24: مبنای این مرحله شواهد مستند در فایل v38 است؛ دریافت مجدد مستقل اسناد کدال در این محیط ممکن نشد. | O24: =IF(COUNTIF($A$4:A24,A24)=1,1,0) -> 1
A25: ومعادن | B25: ='Turnover نهایی'!V25 -> بله | C25: =IF(B25="بله",1,IF(B25="خیر",0,"")) -> 1 | D25: INHERITED_WITH_LIMITATION | E25: بله | F25: =IF(AND(E25="بله",ISNUMBER(C25)),C25,"") -> 1 | I25: انتقال کنترل شده مقدار v38؛ تایید مجدد مستقل همه منابع این شرکت در v39 انجام نشده است. | J25: SRC_VMDN_1404_002 | گزارش فعالیت هیئت مدیره | ۱۴۰۳ | ۴۰ | Snapshot مبنا برای ۱۴۰۳ SRC_VMDN_1404_001 | گزارش فعالیت هیئت مدیره | ۱۴۰۴ | ۴۳ | Snapshot سال ۱۴۰۴ SRC_VMDN_1404_004 | افشای نوع ۱۹ | ۱۴۰۴ | ۱ | تایید تغییر نماینده فولاد سنگ SRC_VMDN_1404_003 | افشای نوع ۱۹ | ۱۴۰۴ | ۱ | تایید تغییر نماینده فولاد مبارکه و ریاست | K25: https://www.codal.ir/Reports/Attachment.aspx?LetterSerial=AcoEbrF1YWBxnIP9D2INbA%3d%3d https://www.codal.ir/Reports/Attachment.aspx?LetterSerial=bRnwYafN0uOG5s7eZOOObOOObCPw%3d%3d https://www.codal.ir/Reports/Decision.aspx?LetterSerial=GYYJgW0mQQQaQQQdbvnpR6QLaHlA%3d%3d&rt=2&let=19&ct=0&ft=-1 https://www.codal.ir/Reports/Decision.aspx?LetterSerial=AHwQQQaQQQkHcUkc0pfBa2dXOOObOOOE3Q%3d%3d&rt=2&let=19&ct=0&ft=-1 | N25: پذیرش به معنی نبود تعارض باز ثبت شده در فایل است؛ نه تایید مستقل کامل اسناد اولیه. | O25: =IF(COUNTIF($A$4:A25,A25)=1,1,0) -> 1
A26: وامید | B26: ='Turnover نهایی'!V26 -> خیر | C26: =IF(B26="بله",1,IF(B26="خیر",0,"")) -> 0 | D26: INHERITED_WITH_LIMITATION | E26: بله | F26: =IF(AND(E26="بله",ISNUMBER(C26)),C26,"") -> 0 | I26: انتقال کنترل شده مقدار v38؛ تایید مجدد مستقل همه منابع این شرکت در v39 انجام نشده است. | J26: SRC_VAMD_1404_002 | گزارش فعالیت هیئت مدیره | ۱۴۰۳ | ۶۹ | Snapshot مبنا برای ۱۴۰۳ SRC_VAMD_1404_001 | گزارش فعالیت هیئت مدیره | ۱۴۰۴ | ۶۹ | Snapshot مبنا برای ۱۴۰۴ SRC_VAMD_1404_005 | افشای نوع ۱۹ اصلاحیه | ۱۴۰۴ | ۱ | کنترل تغییر اشخاص حقوقی و تداوم نمایندگان SRC_VAMD_1404_006 | افشای نوع ۱۹ | ۱۴۰۴ | ۱ | کنترل مستقل ترکیب | K26: https://www.codal.ir/Reports/Attachment.aspx?LetterSerial=CM4mqa3Wz2h9LMqk4uVACQ%3d%3d https://www.codal.ir/Reports/Attachment.aspx?LetterSerial=L3pmVuuRgm42MhLxuM1ElQ%3d%3d https://www.codal.ir/Reports/Decision.aspx?LetterSerial=1UEyCQ9gyduKzNiiDDNXUA%3d%3d&rt=2&let=19&ct=0&ft=-1 https://www.codal.ir/Reports/Decision.aspx?LetterSerial=heZfln7kl6v8fiuPpe5P4g%3d%3d&rt=2&let=19&ct=0&ft=-1 | N26: پذیرش به معنی نبود تعارض باز ثبت شده در فایل است؛ نه تایید مستقل کامل اسناد اولیه. | O26: =IF(COUNTIF($A$4:A26,A26)=1,1,0) -> 1
A27: خساپا | B27: ='Turnover نهایی'!V27 -> خیر | C27: =IF(B27="بله",1,IF(B27="خیر",0,"")) -> 0 | D27: V38_CONFIRMED | E27: بله | F27: =IF(AND(E27="بله",ISNUMBER(C27)),C27,"") -> 0 | G27: کورش پرویزیان | H27: کورش پرویزیان | I27: مقایسه هویت رئیس در دو نقطه از بازسازی سطح کرسی v38؛ عدم تغییر سایر سمت ها ملاک نیست. | J27: Turnover Seat Reconstruction؛ 1295938 / 1386511 | K27: https://www.codal.ir/Reports/Decision.aspx?LetterSerial=0rlsOOObOOOEFaa9IMoCD90IUbxA%3d%3d&rt=0&let=19&ct=0&ft=-1 https://www.codal.ir/Reports/Decision.aspx?LetterSerial=UJ1so0i61H6WpTMWJ3OsCA%3d%3d&rt=0&let=19&ct=0&ft=-1 | N27: مبنای این مرحله شواهد مستند در فایل v38 است؛ دریافت مجدد مستقل اسناد کدال در این محیط ممکن نشد. | O27: =IF(COUNTIF($A$4:A27,A27)=1,1,0) -> 1
A28: همراه | B28: ='Turnover نهایی'!V28 -> خیر | C28: =IF(B28="بله",1,IF(B28="خیر",0,"")) -> 0 | D28: INHERITED_WITH_LIMITATION | E28: بله | F28: =IF(AND(E28="بله",ISNUMBER(C28)),C28,"") -> 0 | I28: انتقال کنترل شده مقدار v38؛ تایید مجدد مستقل همه منابع این شرکت در v39 انجام نشده است. | J28: SRC_HMRH_1404_002 | گزارش فعالیت هیئت مدیره | ۱۴۰۳ | ۵ | Snapshot مبنا ۱۴۰۳ SRC_HMRH_1404_001 | گزارش فعالیت هیئت مدیره | ۱۴۰۴ | ۵ | Snapshot مبنا ۱۴۰۴ SRC_HMRH_1404_005 | افشای نوع ۱۹ | ۱۴۰۴ | ۱ | بازتایید ثبات نمایندگان و اشخاص حقوقی | K28: https://www.codal.ir/Reports/Attachment.aspx?LetterSerial=qF6WQQQaQQQvb3G9yQQQaQQQVuknoGcUQQ%3d%3d https://www.codal.ir/Reports/Attachment.aspx?LetterSerial=Ln6R9zsWXNJqeuz97OOObOOOaACw%3d%3d https://www.codal.ir/Reports/Decision.aspx?LetterSerial=EkFsjyhmhfXBQoQQQaQQQTg7cqCw%3d%3d&rt=5&let=19&ct=0&ft=-1 | N28: پذیرش به معنی نبود تعارض باز ثبت شده در فایل است؛ نه تایید مستقل کامل اسناد اولیه. | O28: =IF(COUNTIF($A$4:A28,A28)=1,1,0) -> 1
A29: وبملت | B29: ='Turnover نهایی'!V29 -> خیر | C29: =IF(B29="بله",1,IF(B29="خیر",0,"")) -> 0 | D29: INHERITED_WITH_LIMITATION | E29: بله | F29: =IF(AND(E29="بله",ISNUMBER(C29)),C29,"") -> 0 | I29: انتقال کنترل شده مقدار v38؛ تایید مجدد مستقل همه منابع این شرکت در v39 انجام نشده است. | J29: SRC_MELT_1404_006 | افشای نوع ۱۹ | ۱۴۰۳ | ۱ | Snapshot اشخاص حقیقی ۱۴۰۳ SRC_MELT_1404_005 | افشای نوع ۱۹ | ۱۴۰۴ | ۱ | Snapshot اشخاص حقیقی ۱۴۰۴؛ فقط تغییر سمت | K29: https://www.codal.ir/Reports/Decision.aspx?LetterSerial=pMyRiSQQQaQQQwMIoymmCCqmzwtg%3d%3d&rt=3&let=19&ct=0&ft=-1 https://www.codal.ir/Reports/Decision.aspx?LetterSerial=jqQzOOObOOOZ5mOOObOOO0IdbSC6088ERA%3d%3d&rt=3&let=19&ct=0&ft=-1 | N29: پذیرش به معنی نبود تعارض باز ثبت شده در فایل است؛ نه تایید مستقل کامل اسناد اولیه. | O29: =IF(COUNTIF($A$4:A29,A29)=1,1,0) -> 1
A30: وبصادر | B30: ='Turnover نهایی'!V30 -> خیر | C30: =IF(B30="بله",1,IF(B30="خیر",0,"")) -> 0 | D30: INHERITED_WITH_LIMITATION | E30: بله | F30: =IF(AND(E30="بله",ISNUMBER(C30)),C30,"") -> 0 | I30: انتقال کنترل شده مقدار v38؛ تایید مجدد مستقل همه منابع این شرکت در v39 انجام نشده است. | J30: SRC_VBSD_1404_002 | گزارش فعالیت هیئت مدیره | ۱۴۰۳ | ۳۸ تا ۳۹ | Snapshot مبنا ۱۴۰۳ SRC_VBSD_1404_001 | گزارش فعالیت هیئت مدیره | ۱۴۰۴ | ۴۵ تا ۴۶ | Snapshot مبنا ۱۴۰۴ | K30: https://www.codal.ir/Reports/Attachment.aspx?LetterSerial=HChwyLb11ZnzYeIEeB3Jng%3d%3d https://www.codal.ir/Reports/Attachment.aspx?LetterSerial=p0cfFj1rDsXiFZsu35tCWw%3d%3d | N30: پذیرش به معنی نبود تعارض باز ثبت شده در فایل است؛ نه تایید مستقل کامل اسناد اولیه. | O30: =IF(COUNTIF($A$4:A30,A30)=1,1,0) -> 1
A31: وپاسار | B31: ='Turnover نهایی'!V31 -> نامشخص | C31: =IF(B31="بله",1,IF(B31="خیر",0,"")) | D31: MISSING | E31: خیر | F31: =IF(AND(E31="بله",ISNUMBER(C31)),C31,"") | I31: انتقال کنترل شده مقدار v38؛ تایید مجدد مستقل همه منابع این شرکت در v39 انجام نشده است. | J31: SRC_VPSR_1404_001 | گزارش فعالیت هیئت مدیره منتهی به ۱۴۰۳/۱۲/۳۰ | ۱۴۰۳ | گزارش ۴۵ صفحه ای | بسته کاربر منبع FY1404 یا Type19 مناسب ندارد SRC_VPSR_1404_001 | گزارش فعالیت هیئت مدیره | ۱۴۰۳ | ۹ | FY1403 موجود است؛ FY1404 در آرشیو بارگذاری شده یافت نشد | K31: https://www.codal.ir/Reports/Attachment.aspx?LetterSerial=Cxkdj8wztt52xU9MoBXp2w%3d%3d | M31: DOCUMENT_MISSING | N31: داده نامشخص به صفر تبدیل نشد. سرنخ گزارش کنترل های داخلی 1526305 پیدا شد ولی متن و امضاهای آن در دسترس نبود. | O31: =IF(COUNTIF($A$4:A31,A31)=1,1,0) -> 1
A32: حکشتی | B32: ='Turnover نهایی'!V32 -> نامشخص | C32: =IF(B32="بله",1,IF(B32="خیر",0,"")) | D32: MISSING | E32: خیر | F32: =IF(AND(E32="بله",ISNUMBER(C32)),C32,"") | I32: انتقال کنترل شده مقدار v38؛ تایید مجدد مستقل همه منابع این شرکت در v39 انجام نشده است. | J32: Iran_BSI_v33_Phase4_2K_FinalTurnoverClosure.xlsx | شرکت های Seat Level | داده شخص حقیقی برای Turnover قابل اتکا نبود | K32: برای ردیابی پایه به فایل v33 و Source_IDهای همان فاز مراجعه شود | M32: PERSON_LEVEL_UNAVAILABLE | N32: داده نامشخص به صفر تبدیل نشد. نام رئیس در یک فهرست تاریخی انجمن کافی برای دو نقطه مقایسه یا تطبیق پنج نماینده نیست. | O32: =IF(COUNTIF($A$4:A32,A32)=1,1,0) -> 1
A33: شپدیس | B33: ='Turnover نهایی'!V33 -> بله | C33: =IF(B33="بله",1,IF(B33="خیر",0,"")) -> 1 | D33: V38_CONFIRMED | E33: بله | F33: =IF(AND(E33="بله",ISNUMBER(C33)),C33,"") -> 1 | G33: هوشنگ گودرزی | H33: حسن شاه‌ولدی | I33: مقایسه هویت رئیس در دو نقطه از بازسازی سطح کرسی v38؛ عدم تغییر سایر سمت ها ملاک نیست. | J33: Turnover Seat Reconstruction؛ 1309386 / 1443721 | K33: https://www.codal.ir/Reports/Decision.aspx?LetterSerial=C4XsKe3dMCJ7F1MqOaUJBw%3d%3d&rt=0&let=19&ct=0&ft=-1 https://www.codal.ir/Reports/Decision.aspx?LetterSerial=Lh6dCOOObOOOOOObOOOHmUIfwOOObOOOrvn9DNRQ%3d%3d&rt=0&let=19&ct=0&ft=-1 | N33: مبنای این مرحله شواهد مستند در فایل v38 است؛ دریافت مجدد مستقل اسناد کدال در این محیط ممکن نشد. | O33: =IF(COUNTIF($A$4:A33,A33)=1,1,0) -> 1
A37: معیار | B37: مقدار | C37: توضیح
A38: پوشش عددی موجود | B38: =COUNT(C4:C33) -> 27 | C38: تعداد کدهای صفر یا یک بدون حذف تعارض
A39: بدون تعارض باز ثبت شده | B39: =COUNT(F4:F33) -> 26 | C39: پوشش محافظه کارانه؛ شواهد موروثی با محدودیت
A40: ورودی نامشخص | B40: =COUNTIF(D4:D33,"MISSING") -> 3 | C40: رمپنا، وپاسار، حکشتی
A41: تعارض باز | B41: =COUNTIF(D4:D33,"NEEDS_REVIEW") -> 1 | C41: فملی؛ ورودی خام نگهداری شده است
A42: تغییر رئیس در مجموعه محافظه کارانه | B42: =COUNTIFS(E4:E33,"بله",F4:F33,1) -> 14 | C42: وجود تغییر به معنی بهتر یا بدتر شدن کیفیت نیست
A43: بدون تغییر در مجموعه محافظه کارانه | B43: =COUNTIFS(E4:E33,"بله",F4:F33,0) -> 12 | C43: صفر واقعی فقط در مجموعه قابل استفاده
...

Sheet Sources v39
A1: فهرست شواهد و محدودیت دسترسی v39
A2: تاریخ بررسی ۲۰۲۶/۱۰/۰۲؛ داده دریافت نشده به عنوان شاهد قطعی استفاده نشده است.
A3: شناسه | B3: شرکت | C3: عنوان | D3: تاریخ یا ردیابی | E3: نوع منبع | F3: نشانی یا فایل | G3: روش مشاهده | H3: یافته | I3: محدودیت
A4: V39S01 | B4: وتجارت | C4: صفحه فارسی هیئت مدیره بانک تجارت | D4: بدون تاریخ موثر | E4: صفحه رسمی بانک | F4: https://www.tejaratbank.ir/web_directory/1679-Board-of-Directors-and-Director.html | G4: متن نمایه شده در جستجوی وب | H4: چهار نام درج شده و نام شریفیان در فهرست دیده نمی شود. | I4: فقط موید ترکیب فعلی؛ نه سند تاریخ خروج و نه تصویر قطعی پایان ۱۴۰۴.
A5: V39S02 | B5: وتجارت | C5: صفحه انگلیسی هیئت مدیره بانک تجارت | D5: بدون تاریخ موثر | E5: صفحه رسمی بانک | F5: https://www.tejaratbank.ir/general_content/1520654-Board-Of-Directors.html | G5: متن نمایه شده در جستجوی وب | H5: پنج نام دارد و حمیدرضا شریفیان را نایب رئیس معرفی می کند. | I5: با نسخه فارسی یکسان نیست؛ تاریخ خروج از صفحه وب قابل تعیین نیست.
A6: V39S03 | B6: وتجارت | C6: خبر انتصاب رئیس و نایب رئیس بانک تجارت | D6: ۱۴۰۱/۱۲/۲۹ | E6: خبر رسمی بانک | F6: https://www.tejaratbank.ir/news/2061976-tejaratbank.html | G6: متن نمایه شده در جستجوی وب | H6: انتخاب ترک تبریزی و شریفیان به ریاست و نایب رئیسی را گزارش می کند. | I6: این سند تاریخی درباره آغاز سمت است و خروج شریفیان در ۱۴۰۴ را اثبات نمی کند.
A7: V39S04 | B7: وپاسار | C7: فراداده گزارش کنترل های داخلی در تاریخ ۱۴۰۴/۱۲/۲۹ | D7: انتشار ۱۴۰۵/۰۲/۲۷؛ ردیابی 1526305 | E7: فهرست اطلاعیه های ذخیره شده در پروژه | F7: https://www.codal.ir/Reports/Decision.aspx?LetterSerial=UtkvD7QAtPic497u28Cz6g%3d%3d&rt=3&let=90&ct=0&ft=-1 | G7: فراداده محلی خوانده شد؛ متن گزارش دریافت نشد | H7: گزارش دوره هدف در فهرست پروژه وجود دارد؛ ردیف کامل در target_filings.json نگهداری شد. | I7: وجود فراداده، نام امضاکنندگان یا ترکیب هیئت مدیره را ثابت نمی کند. این گزارش با گزارش فعالیت هیئت مدیره تفاوت دارد.
A8: V39S05 | B8: حکشتی | C8: معرفی کشتیرانی جمهوری اسلامی ایران در فهرست اعضای انجمن | D8: ۱۴۰۳/۱۰/۱۷ | E8: فهرست اعضای انجمن کشتیرانی | F8: https://saoi.ir/کشتیرانی-جمهوری-اسلامی-ایران/ | G8: متن نمایه شده در جستجوی وب | H8: مدیرعامل محمدرضا مدرس خیابانی و رئیس هیئت مدیره علی مسیبی بهروز درج شده اند. | I8: فقط سرنخ تاریخی؛ نمایندگی پنج کرسی حقوقی یا ترکیب پایان ۱۴۰۴ را نشان نمی دهد.
A9: V39S06 | B9: وتجارت | C9: اطلاعیه اصلاحی ترکیب هیئت مدیره | D9: انتشار ۱۴۰۴/۰۹/۱۵؛ ردیابی 1444154 | E9: کدال طبق شواهد ذخیره شده v38 | F9: https://www.codal.ir/Reports/Decision.aspx?LetterSerial=tL1npzfj3XSDR4oEqs1VIw%3d%3d&rt=3&let=19&ct=0&ft=-1 | G9: شرح و بازسازی داخل فایل v38؛ دریافت مجدد ناموفق | H9: بازسازی v38 چهار عضو را در پایان دوره ثبت کرده است. | I9: نسخه اولیه ردیابی 1443078 و اصلاحیه درباره شریفیان ناسازگار گزارش شده اند؛ v39 سند تازه خروج دریافت نکرد.
A10: V39S07 | B10: حکشتی | C10: اطلاعیه ترکیب هیئت مدیره | D10: انتشار ۱۴۰۴/۰۸/۱۸؛ ردیابی 1433770 | E10: کدال طبق شواهد ذخیره شده v38 | F10: https://www.codal.ir/Reports/Decision.aspx?LetterSerial=ag9Rd4I5seaRFhQQQaQQQiZlm5lQ%3d%3d&rt=2&let=19&ct=0&ft=-1 | G10: شرح داخل فایل v38؛ دریافت مجدد ناموفق | H10: پنج شخص حقوقی در بازسازی موجود هستند؛ نام نمایندگان برای محاسبه فردی کافی نیست. | I10: عبارت فاقد نماینده در اسناد به صفر بودن گردش یا نبود واقعی نماینده تبدیل نشد.
A11: V39S08 | B11: وپاسار | C11: گزارش فعالیت هیئت مدیره سال ۱۴۰۳ | D11: انتشار ۱۴۰۴/۰۶/۱۶؛ ردیابی 1396276 | E11: کدال طبق شواهد ذخیره شده v38 | F11: https://www.codal.ir/Reports/Attachment.aspx?LetterSerial=Cxkdj8wztt52xU9MoBXp2w%3d%3d | G11: شرح داخل فایل v38؛ دریافت مجدد ناموفق | H11: v38 اختلاف فهرست هفت نفره گزارش با پنج نفره تصمیمات مجمع را ثبت کرده است. | I11: اصلی یا علی البدل بودن، تاریخ موثر و پنجره دو فهرست هنوز تطبیق نشده است.
A12: V39S09 | B12: هر سه شرکت | C12: گزارش آزمون دسترسی مستقیم | D12: زمان همین بررسی | E12: گزارش فنی محیط | F12: fetch_log.json | G12: خطای تفکیک نام دامنه در درخواست مستقیم؛ بازکردن صفحات رسمی با ابزار وب نیز ناموفق | H12: متن کامل اسناد جدید کدال از این مسیر دریافت نشد. | I12: شکست دسترسی به معنی نبود یا منتشر نشدن سند نیست.
A13: V39S10 | B13: ۳۰ شرکت | C13: فایل مبنا و بازسازی سطح کرسی v38 | D13: فایل تحویلی کاربر | E13: داده و ممیزی قبلی پروژه | F13: Iran_BSI_v38_Turnover_Resolved.xlsx | G13: فایل کامل با openpyxl خوانده شد | H13: مبنای محاسبه CR1A ستون V و برای هشت شرکت نام رئیس از برگه بازسازی سطح کرسی استخراج شد. | I13: v39 جایگزین بازخوانی مستقل همه اسناد اولیه ۳۰ شرکت نیست؛ محدودیت شواهد قبلی حفظ شد.

Sheet QA v39
A1: کنترل کیفیت و محاسبات
A2: گزارش کنترل محاسبات، حفظ داده های خام و تفاوت با فایل مبنا.
A3: کنترل | B3: نتیجه | C3: روش و دامنه
A4: تعداد ردیف شرکت | B4: ='CR1A v39'!B44 -> 30 | C4: باید ۳۰ باشد
A5: تعداد نام یکتا | B5: ='CR1A v39'!B49 -> 30 | C5: COUNTIF تجمعی؛ باید ۳۰ باشد
A6: کدهای موجود CR1A | B6: ='CR1A v39'!B38 -> 27 | C6: باید ۲۷ باشد
A7: پوشش محافظه کارانه | B7: ='CR1A v39'!B39 -> 26 | C7: باید ۲۶ باشد؛ تایید مستقل جدید همه اسناد نیست
A8: جمع تغییر و عدم تغییر | B8: ='CR1A v39'!B42+'CR1A v39'!B43 -> 26 | C8: باید برابر پوشش محافظه کارانه باشد
A9: کامل بودن تفکیک | B9: ='CR1A v39'!B39+'CR1A v39'!B40+'CR1A v39'!B41 -> 30 | C9: باید برابر ۳۰ باشد
A10: تغییر ورودی خام گردش و رئیس | B10: 0 | C10: مقایسه همه سلول های Turnover نهایی با v38؛ انتظار صفر تفاوت
A11: تطبیق هویت رئیس در بازسازی v38 | B11: 8 | C11: هشت شرکت با نام رئیس در هر دو نقطه؛ کد محاسبه با ستون V یکسان بود
A12: فرمول های تاریخی با ورودی متن | B12: 36 | C12: در Audit Coverage با ISNUMBER محافظت و علت فقدان عدد برچسب گذاری شد
A13: فرمول یکتایی سازگار شده | B13: 1 | C13: تبدیل SUMPRODUCT با COUNTIF آرایه ای به COUNTIF تجمعی و SUM
A14: تعداد خطای محاسبات پس از بازگشایی | B14: 0 | C14: بازمحاسبه انجام و همه سلول های خطای محاسبات بررسی شد؛ هیچ خطای اکسل در مقادیر ذخیره شده باقی نماند.
A15: تعداد فرمول ها | B15: 926 | C15: تعداد فرمول های واقعی فایل؛ متن فرمول های قدیمی در ثبت تغییرات به عنوان متن نگهداری می شوند.
A16: تعداد سلول های تغییر یافته موجود | B16: 156 | C16: تفاوت سلول های موجود؛ برگه های جدید جدا از این شمارش اند
A17: هش فایل مبنا | B17: a38b0c234772920be07af7b7ff8f00754cf8f3c7b582044269856b6b003cb483 | C17: SHA256؛ فایل مبنا نباید تغییر کرده باشد
A18: مرز اعتبار خروجی | B18: محاسباتی و ردیابی | C18: این بررسی به معنی تایید مستقل همه اعداد تاریخی فایل یا بسته شدن سه پرونده نیست

Sheet راهنمای نسخه v37
A1: راهنمای فایل نهایی Iran BSI v37
A2: این فایل سه خروجی v36 را در یک Master Workbook یکپارچه می کند و هیچ داده ای از فایل های مرجع حذف نشده است.
A4: بخش | B4: هدف | C4: وضعیت | D4: منبع | E4: روش یا قاعده | F4: خروجی قابل استفاده | G4: محدودیت | H4: یادداشت
A5: خلاصه نهایی | B5: جمع بندی ممیزی و معماری | C5: به روز شده | D5: v36 Audit + Candidates | E5: فقط اعداد و نقش های ممیزی شده | F5: ارائه مدیریتی | G5: گپ های باز جداگانه ثبت شده | H5: نقطه شروع فایل
A6: جدول استاد | B6: جدول Measureها | C6: به روز شده | D6: Audit Measureها + Candidate N02 | E6: Coverage، Formula، Source و Role کنار هم | F6: جلسه استاد | G6: N02 هنوز Composite نیست | H6: مناسب ارائه
A7: معماری به روز شده | B7: تصمیم نقش Measureها | C7: به روز شده | D7: Final Audit Verdict | E7: تفکیک Scale Up، Structural، Control، Robustness و Targeted | F7: طراحی Phase 5 | G7: REF08 هنوز Targeted | H7: جلوگیری از دوباره شماری
A8: Constructهای مستقل | B8: شمارش Constructهای واقعی | C8: به روز شده | D8: Audit Redundancy | E8: Measureهای مکمل یک Construct دوباره شمرده نمی شوند | F8: معماری مفهومی | G8: ۹ Construct فعلی | H8: SEP07 کنترل است
A9: Turnover نهایی | B9: داده شرکت به شرکت | C9: اصلاح شده | D9: v36 Final Integrated Audited | E9: فرمول صورت و مخرج | F9: تحلیل گردش | G9: چند Source Review باز | H9: خودرو و فارس اصلاح شده اند
A10: Audit sheets | B10: ممیزی مستقل | C10: حفظ کامل | D10: Iran_BSI_v36_Independent_Audit.xlsx | E10: بازتولید مستقل | F10: ردیابی خطا و اصلاح | G10: Fully Verified تعریف سخت گیرانه دارد | H10: تمام Sheetها در همین فایل کپی شده اند
A11: Candidate sheets | B11: کشف Measure جدید | C11: حفظ کامل | D11: Iran_BSI_v36_Additional_Measure_Candidates.xlsx | E11: Feasibility + Variation + Scalability | F11: R&D Measureها | G11: فقط N02 Scale Up Candidate شد | H11: هیچ Candidate جدید وارد Composite نشده
A12: فرمول ها | B12: کنترل ارجاع و Recalc در Excel | C12: بدون #REF در فرمول ها | D12: v36 Audit + QA v37 | E12: ارجاع فرمول ها بررسی شده و فایل روی Automatic Calculation تنظیم شده است | F12: پس از اولین باز کردن در Excel دوباره محاسبه می شود | G12: مقادیر فرمولی در این محیط به صورت عددی مستقل Recalculate نشده اند | H12: پس از باز کردن در Excel یک Save انجام شود

Sheet راهنمای محاسبات و منابع
A1: راهنمای محاسبات، منابع و ردیابی داده ها
A2: هر عدد یا از منبع رسمی ردیابی می شود یا روش محاسبه آن در این فایل مشخص است
A4: کد | B4: معیار | C4: روش محاسبه یا تعریف عملیاتی | D4: منبع تصمیم یا برگه محاسباتی | E4: منبع داده خام | F4: نوع خروجی | G4: قاعده Missingness | H4: نکته کنترل کیفیت
A5: S1A | B5: پروکسی استقلال ساختاری هیئت مدیره | C5: تعداد اعضای غیرموظف تقسیم بر تعداد اعضای هیئت مدیره با وضعیت موظف یا غیرموظف قابل تایید. این متغیر استقلال صریح نیست و فقط پروکسی ساختاری است. | D5: Iran_BSI_v30_Phase4_2H_PreAdvisorReview.xlsx | معیارهای قابل توسعه، معماری سازه ای و بررسی Separation | E5: داده خام وضعیت موظف یا غیرموظف اعضا از افشاهای رسمی هیئت مدیره | F5: محاسباتی | G5: Missing و قابل اعمال نیست صفر نمی شوند | H5: بدون حدس؛ Source_ID و شواهد خام حفظ می شوند
A6: V1 | B6: تنوع رشته تحصیلی | C6: Blau خام برابر است با ۱ منهای مجموع مربع سهم هر گروه رشته تحصیلی. اگر اطلاعات رشته تحصیلی عضو فعال برای محاسبه کامل نباشد، Missing به صفر تبدیل نمی شود. | D6: Iran_BSI_v30_Phase4_2H_PreAdvisorReview.xlsx | تنوع تحصیلی و معماری آماده استاد | E6: Iran_BSI_Variety_SubPilot_A_Batch1_v2.xlsx و نسخه های تکمیلی Variety | F6: محاسباتی | G6: Missing و قابل اعمال نیست صفر نمی شوند | H6: بدون حدس؛ Source_ID و شواهد خام حفظ می شوند
A7: VAR06_Strict | B7: تنوع سابقه حرفه ای، نسخه سخت گیرانه | C7: ابتدا سابقه حرفه ای صریح در گروه های از پیش تعریف شده کدگذاری می شود. عنوان عمومی مدیریتی بدون مسیر وظیفه ای به تنهایی طبقه بندی نمی شود. سپس Blau برابر ۱ منهای مجموع مربع سهم گروه ها محاسبه می شود. | D7: Iran_BSI_v30_Phase4_2H_PreAdvisorReview.xlsx | تنوع سابقه حرفه ای | E7: کدگذاری سابقه حرفه ای اعضا از رزومه و افشاهای رسمی | F7: محاسباتی | G7: Missing و قابل اعمال نیست صفر نمی شوند | H7: بدون حدس؛ Source_ID و شواهد خام حفظ می شوند
A8: VAR10 | B8: تخصص مالی مستند ترکیبی | C8: تعداد اعضایی که تخصص مالی آنها از تحصیلات یا سابقه حرفه ای به طور مستند قابل تایید است تقسیم بر تعداد اعضای قابل ارزیابی. | D8: Iran_BSI_v30_Phase4_2H_PreAdvisorReview.xlsx و Iran_BSI_v31_Phase4_2I_MaximumMeasureRecovery.xlsx | تخصص هیئت مدیره | E8: تحصیلات و سابقه حرفه ای رسمی اعضای هیئت مدیره | F8: محاسباتی | G8: Missing و قابل اعمال نیست صفر نمی شوند | H8: بدون حدس؛ Source_ID و شواهد خام حفظ می شوند
A9: CR1A | B9: تغییر رئیس هیئت مدیره | C9: هویت رئیس هیئت مدیره در پنجره زمانی مشترک با توالی افشاهای رسمی مقایسه می شود. تغییر تاییدشده برابر بله و نبود تغییر تاییدشده برابر خیر است. جهت کیفیت از پیش مثبت یا منفی فرض نمی شود. | D9: CR1A v39؛ Turnover Seat Reconstruction v38؛ تاریخچه v30 محفوظ است | E9: افشاهای رسمی انتصاب و تغییر اعضای هیئت مدیره | F9: استخراج و مقایسه | G9: نامشخص و متعارض صفر نمی شوند؛ پوشش عددی از پوشش محافظه کارانه جدا است. تاریخ موثر مبنای اصلی است و حساسیت انتشار جم حفظ می شود. | H9: بدون حدس؛ Source_ID و شواهد خام حفظ می شوند
A10: AUD01 | B10: وجود کمیته حسابرسی | C10: وجود کمیته حسابرسی فقط با افشای رسمی صریح تایید می شود. نبود منبع کافی به معنی صفر نیست. | D10: Iran_BSI_v30_Phase4_2H_PreAdvisorReview.xlsx و Iran_BSI_v31_Phase4_2I_MaximumMeasureRecovery.xlsx | کمیته حسابرسی | E10: گزارش های فعالیت هیئت مدیره و جداول کمیته حسابرسی | F10: استخراج و مقایسه | G10: Missing و قابل اعمال نیست صفر نمی شوند | H10: بدون حدس؛ Source_ID و شواهد خام حفظ می شوند
A11: AUD02 | B11: اندازه کمیته حسابرسی | C11: تعداد اعضای کمیته حسابرسی فقط در شرکت هایی که فهرست اعضا به طور کامل قابل خواندن و تایید است. | D11: Iran_BSI_v31_Phase4_2I_MaximumMeasureRecovery.xlsx | کمیته حسابرسی خام و معیارهای کمیته حسابرسی | E11: فهرست رسمی اعضای کمیته حسابرسی | F11: محاسباتی | G11: Missing و قابل اعمال نیست صفر نمی شوند | H11: بدون حدس؛ Source_ID و شواهد خام حفظ می شوند
A12: IRN01 | B12: سهم کرسی اشخاص حقوقی | C12: تعداد کرسی هایی که صاحب کرسی آنها شخص حقوقی است تقسیم بر کل کرسی های فعال و قابل طبقه بندی هیئت مدیره. | D12: Iran_BSI_v30_Phase4_2H_PreAdvisorReview.xlsx | ساختار اشخاص حقوقی و معیارهای قابل توسعه | E12: جداول رسمی ترکیب هیئت مدیره | F12: محاسباتی | G12: Missing و قابل اعمال نیست صفر نمی شوند | H12: بدون حدس؛ Source_ID و شواهد خام حفظ می شوند
A13: IRN02 | B13: سهم کرسی اشخاص حقیقی | C13: تعداد کرسی های مستقیم اشخاص حقیقی تقسیم بر کل کرسی های فعال و قابل طبقه بندی. در طبقه بندی کامل، مکمل ریاضی IRN01 است. | D13: Iran_BSI_v30_Phase4_2H_PreAdvisorReview.xlsx | ساختار اشخاص حقوقی و معیارهای قابل توسعه | E13: جداول رسمی ترکیب هیئت مدیره | F13: محاسباتی | G13: Missing و قابل اعمال نیست صفر نمی شوند | H13: بدون حدس؛ Source_ID و شواهد خام حفظ می شوند
A14: SEP07 | B14: تفکیک مدیرعامل و رئیس هیئت مدیره | C14: اگر مدیرعامل و رئیس هیئت مدیره دو شخص متفاوت باشند مقدار تفکیک تایید می شود. هویت ها فقط از افشای رسمی گرفته می شوند. | D14: Iran_BSI_v30_Phase4_2H_PreAdvisorReview.xlsx | تفکیک مدیرعامل و رئیس هیئت مدیره | E14: هویت رئیس و مدیرعامل در افشاهای رسمی | F14: استخراج و مقایسه | G14: Missing و قابل اعمال نیست صفر نمی شوند | H14: بدون حدس؛ Source_ID و شواهد خام حفظ می شوند
A15: REF05 | B15: نرخ گردش شخص حقیقی هیئت مدیره | C15: تعداد کرسی های قابل مقایسه که شخص حقیقی آنها بین Snapshot ۱۴۰۳ و ۱۴۰۴ تغییر کرده تقسیم بر تعداد کرسی های دارای شخص حقیقی قابل مقایسه. تغییر سمت به تنهایی Turnover نیست و کرسی خالی به صورت خودکار تغییر نماینده محسوب نمی شود. | D15: Turnover نهایی | ستون های صورت گردش فردی و مخرج گردش فردی | E15: v33 و شش Batch بررسی بصری و تطبیق اسناد کدال | F15: محاسباتی | G15: Missing و قابل اعمال نیست صفر نمی شوند | H15: بدون حدس؛ Source_ID و شواهد خام حفظ می شوند
... A21: CORR | B21: همبستگی Measureها | C21: همبستگی Pearson روی نرخ های موجود و قابل مقایسه. این خروجی فقط برای بررسی همپوشانی است و به تنهایی مبنای انتخاب کیفیت نیست. | D21: برگه Correlation | E21: محاسبه از نرخ های تاییدشده Turnover نهایی | F21: محاسباتی | G21: Missing و قابل اعمال نیست صفر نمی شوند | H21: بدون حدس؛ Source_ID و شواهد خام حفظ می شوند
A24: ردیابی برگه های فایل
A25: برگه | B25: هدف | C25: روش تولید | D25: منبع یا ورودی | E25: فرمول یا منطق | F25: آیا داده خام دارد؟ | G25: کنترل کیفیت | H25: یادداشت
A26: خلاصه نهایی | B26: جمع بندی تغییر Coverage و معماری | C26: تجمیع خروجی های سایر برگه ها | D26: پوشش نهایی، معماری به روز شده و Audit Trail | E26: مقایسه قبل و بعد | F26: خیر | G26: سازگاری اعداد با برگه های مرجع | H26: خروجی ارائه ای
A27: جدول استاد | B27: نمایش Measureهای قابل توسعه | C27: تجمیع معماری و Coverage | D27: معماری به روز شده و پوشش نهایی | E27: Coverage برابر دارای داده تقسیم بر واجد شرایط | F27: خیر | G27: فرمول های Coverage نگهداری شده | H27: خروجی ارائه ای
A28: معماری به روز شده | B28: تصمیم نهایی Measureها | C28: سنتز شواهد فازهای ۴.۲ و Batchها | D28: v30، v31، v33 و v34 | E28: رتبه معماری براساس Coverage، Variation، جهت نظری و مقیاس پذیری | F28: خیر | G28: جهت نظری از Coverage جدا نگه داشته شده
A29: Constructهای مستقل | B29: جلوگیری از دوباره شماری | C29: گروه بندی Measureهای هم سازه | D29: معماری به روز شده | E29: Measureهای مکمل یا تبدیل ریاضی یک Construct مستقل محسوب نمی شوند | F29: خیر | G29: همپوشانی مفهومی کنترل شده
A30: وضعیت ۳۰ شرکت | B30: وضعیت نهایی هر شرکت | C30: تجمیع v33 و Batchهای ۱ تا ۶ | D30: اسناد کدال و فایل های Batch | E30: طبقه بندی تاییدشده، حل نشده، خارج از مخرج | F30: بله | G30: هیچ Missing به صفر تبدیل نشده
A31: Turnover نهایی | B31: محاسبات اصلی گردش و تغییر نماینده | C31: تطبیق دو Snapshot سال ۱۴۰۳ و ۱۴۰۴ | D31: اسناد رسمی کدال، v33 و Batchهای ۱ تا ۶ | E31: نرخ ها از صورت تقسیم بر مخرج محاسبه می شوند | F31: بله | G31: Cutoff، vacancy، تغییر سمت و N/A کنترل شده | H31: مرجع اصلی خانواده Turnover
A32: پوشش نهایی | B32: Coverage خانواده Turnover | C32: شمارش از Turnover نهایی | D32: Turnover نهایی | E32: دارای داده تقسیم بر واجد شرایط | F32: خیر | G32: N/A و خارج از مخرج جدا هستند
A33: Variation نهایی | B33: آمار توصیفی | C33: محاسبه روی نرخ های تاییدشده | D33: Turnover نهایی | E33: کمینه، بیشینه، میانگین، میانه، انحراف معیار و شمارش صفر | F33: خیر | G33: فقط داده تاییدشده
A34: Correlation | B34: بررسی همپوشانی | C34: Pearson روی مشاهدات زوجی | D34: Turnover نهایی | E34: CORREL روی نرخ های موجود | F34: خیر | G34: برای جلوگیری از دوباره شماری
A35: Construct ایران محور | B35: ارزیابی پویایی نمایندگی | C35: سنتز REF08 | D35: Turnover نهایی | E35: شمارش وقوع، میانگین، میانه، کمینه، بیشینه و همبستگی | F35: خیر | G35: فقط شرکت های دارای ساختار نمایندگی حقوقی تاییدشده
A36: ۱۲ شاخص اصلی BSI | B36: Mapping شاخص اصلی به ایران | C36: ممیزی مفهومی و داده ای | D36: v30 و v31 | E36: Direct، Proxy، Robustness، Drop یا Unresolved | F36: خیر | G36: هیچ معادل مستقیم بدون شواهد ادعا نشده
A37: ثبت منابع Batchها | B37: ثبت Source_ID و لینک کدال | C37: استخراج مستقیم از فایل های Batch | D37: اسناد رسمی کدال | E37: بدون محاسبه | F37: بله | G37: ردیابی Source_ID و صفحه | H37: مرجع URL
A38: Audit Trail | B38: تاریخچه تصمیم ها | C38: ثبت تغییرات مرحله ای | D38: v33 و Batchهای ۱ تا ۶ | E38: بدون محاسبه | F38: خیر | G38: قابلیت بازسازی تصمیم
A39: چک لیست نهایی | B39: کنترل پایانی | C39: ممیزی ساختاری فایل | D39: تمام برگه ها | E39: کنترل تعداد شرکت، Missingness، فرمول و تکرار | F39: خیر | G39: باید قبل از تحویل تایید باشد

Sheet گپ های باز
A1: گپ های باز و تاریخچه حل تا v39
A3: ID | B3: موضوع | C3: شرکت یا Measure | D3: مشکل | E3: شاهد | F3: وضعیت | G3: اقدام لازم | H3: قاعده تصمیم
A4: G01 | B4: Turnover identity | C4: تاپیکو | D4: Snapshot FY1403 ناهمتراز و احتمال Look Ahead | E4: Conflict Log C10 | F4: حل شد (v38) | G4: بازبینی سند و Snapshot قبل از Cutoff | H4: Confirmed: Snapshot تاپیکو بازسازی شد
A5: G02 | B5: Turnover identity | C5: کچاد | D5: هویت K برابر N منهای M نقض شده | E5: Conflict Log C13 | F5: حل شد (v38) | G5: بازخوانی Seat Matching | H5: Confirmed: Snapshot مبنا Look-Ahead بود
A6: G03 | B6: Turnover identity | C6: پارسان | D6: Q برابر ۷ با ساختار حقوقی v22 ناسازگار | E6: Conflict Log C11 | F6: حل شد (v38) | G6: بازبینی roster و seat structure | H6: High: Q=5؛ ۵ کرسی حقوقی
A7: G04 | B7: Turnover identity | C7: وتجارت | D7: ساختار حل شده؛ تاریخ خروج شریفیان و ناسازگاری اسناد نیازمند بررسی است. | E7: Conflict Log C12 | F7: باز با شواهد تکمیلی v39 | G7: دریافت سند خروج و تطبیق نسخه اولیه با اصلاحیه | H7: ساختار تایید؛ تاریخ خروج شریفیان Needs Review
A8: G05 | B8: Turnover identity | C8: جم | D8: P کمتر از G | E8: Conflict Log C14 | F8: حل شد (v38) | G8: بازبینی New Member vs Seat Change | H8: P<G مشروع (جابه‌جایی)؛ P=1
A9: G06 | B9: Turnover identity | C9: خساپا | D9: P کمتر از G | E9: Conflict Log C14 | F9: حل شد (v38) | G9: بازبینی جابجایی فرد بین کرسی ها | H9: مقادیر v35 تایید؛ P<G مشروع
A10: G07 | B10: AUD01 page review | C10: ۶ شرکت Keyword Hit | D10: وجود کلیدواژه بدون تایید صفحه | E10: Conflict Log و Audit Committees | F10: حل شد برای ۶ شرکت؛ وپاسار باز | G10: بازبینی صفحه | H10: Keyword Hit به تنهایی YES نیست؛ فقط افشای صریح
A11: G08 | B11: Source URL | C11: ۹ شرکت | D11: URL منبع در رجیستری کامل نیست | E11: Conflict Log C18 | F11: باز | G11: تکمیل Source Registry | H11: نبود URL به معنی نبود Source نیست ولی provenance باید کامل شود
A12: G09 | B12: Source registry | C12: ۴ شرکت | D12: ردیف پایه رجیستری موجود نیست | E12: Conflict Log C18 | F12: باز | G12: افزودن ردیف پایه Source_ID | H12: تمام مقدارهای Raw باید Source داشته باشند
A13: G10 | B13: REF08 | C13: خودرو | D13: دلیل تغییر نماینده تایید نشده | E13: Required Corrections | F13: حل شد (v38) | G13: Source Review | H13: REF08 خودرو = ۱/۵
A14: G11 | B14: ترکیب تاریخی هیئت مدیره | C14: وپاسار | D14: پایان ۱۴۰۴ مستند نیست و پایه پنج یا هفت نفره حل نشده است. | E14: V39S04؛ V39S08 | F14: باز در v39 | G14: دریافت گزارش 1526305 و تطبیق صورتجلسه و امضاها | H14: فراداده سند با متن و فهرست اعضا یکسان نیست
... A16: G13 | B16: تعارض تغییر رئیس | C16: فملی | D16: خیر در v38 با پرچم تعارض قبلی همراه است؛ سند حل کننده در این مرحله دریافت نشد. | E16: CR1A v39؛ Conflict Log C04 | F16: باز در v39 | G16: تطبیق نام رئیس در دو نقطه و افشاهای میانی | H16: از شمارش محافظه کارانه کنار گذاشته شد؛ مقدار خام حذف نشد

Sheet خلاصه نهایی
A1: جمع بندی نهایی ممیزی مستقل Iran BSI
A2: نسخه v39 مبتنی بر فایل v38؛ محاسبات CR1A همگام و سه پرونده سندی با وضعیت واقعی ثبت شدند.
A4: موضوع | B4: وضعیت نهایی | C4: عدد یا دامنه | D4: تفسیر | E4: منبع | F4: روش محاسبه یا مبنا | G4: وضعیت ممیزی | H4: اقدام بعدی
A5: حکم فایل v35 | B5: نیازمند اصلاحات اساسی | C5: V35_REQUIRES_MATERIAL_CORRECTIONS | D5: ممیزی مستقل چند اصلاح عددی و معماری پیدا کرد | E5: Final Audit Verdict | F5: ممیزی بازتولیدپذیری داده، Coverage، فرمول و Source | G5: قطعی | H5: نسخه v35 مبنا قرار نگیرد
A6: نسخه جاری | B6: اصلاحات تاییدشده اعمال شده | C6: v39 CR1A Audit and Open Gaps | D6: همگام سازی تغییر رئیس و اصلاح فرمول های ناسازگار انجام شد؛ داده خام سه شرکت بدون سند تازه تغییر نکرد. | E6: CR1A v39؛ Gap Review v39؛ Changes v39 | F6: فقط اصلاحات دارای شاهد اعمال شده اند | G6: قابل استفاده با محدودیت و گپ باز | H6: بازبینی Source Reviewهای باز
A7: Measureهای موجود برای Scale Up | B7: ۶ Measure | C7: S1A, V1, VAR06, VAR10, AUD01, REF05 | D7: شش Measure موجود پس از ممیزی همچنان قابلیت توسعه دارند | E7: Audit Measureها | F7: شمارش وضعیت SCALE_UP_PRIMARY و SCALE_UP_WITH_LIMITATION در Measureهای موجود | G7: با محدودیت | H7: در طراحی نمونه اصلی حفظ شوند
A8: Measure ساختاری ایران | B8: ۱ Measure | C8: IRN01 | D8: ساختاری است و نباید به صورت مکانیکی Higher Better امتیازدهی شود | E8: Audit Measureها | F8: سهم کرسی های اشخاص حقوقی از کل کرسی های قابل طبقه بندی | G8: با محدودیت | H8: به عنوان Measure ساختاری نگهداری شود
A9: Measureهای کنترلی | B9: ۲ Measure | C9: CR1A و SEP07 | D9: CR1A جهت کیفی روشن ندارد و SEP07 در ۲۶ شرکت شناخته شده Variation صفر دارد | E9: Audit Measureها | F9: طبقه بندی CONTROL_DIAGNOSTIC | G9: قطعی | H9: در Composite اصلی وارد نشوند
A10: Measureهای Robustness موجود | B10: ۲ Measure | C10: AUD02 و IRN02 | D10: AUD02 توصیفی است و IRN02 مکمل دقیق IRN01 است | E10: Audit Redundancy | F10: نقش Robustness و کنترل دوباره شماری | G10: قطعی | H10: فقط در Robustness
A11: REF08 | B11: نیازمند اعتبارسنجی هدفمند | C11: 25 از 25 واجد شرایط (v38) | D11: پوشش عددی REF08 طبق v38 برابر ۲۵ از ۲۵ واجد شرایط است؛ این عدد به معنی بسته شدن پرونده های فردی سه شرکت نیست. | E11: Audit Coverage + Conflict Log | F11: تغییر نماینده حقیقی فقط در کرسی با شخص حقوقی ثابت | G11: NEEDS_SOURCE_REVIEW | H11: قبل از Scale Up بازبینی موارد باز
A12: Constructهای مستقل | B12: ۹ Construct | C12: پس از خروج SEP07 از Construct مستقل | D12: شمارش ۱۰ Construct قبلی اصلاح شد | E12: Final Audit Verdict | F12: گروه بندی Measureهای غیرتکراری پس از Redundancy Audit | G12: قطعی | H12: مبنای معماری فعلی
A13: Candidate جدید قابل توسعه | B13: سهم اعضای دارای دکترا | C13: ۳۰ از ۳۰ شرکت | D13: Variation واقعی دارد ولی با V1 و VAR10 همپوشانی جزئی دارد | E13: Scale Up Candidates | F13: تعداد اعضای دارای مدرک دکترا تقسیم بر اعضای دارای Education Level قابل ارزیابی | G13: SCALE_UP_WITH_LIMITATION | H13: فعلا خارج Composite، در Phase 5 تست شود
A14: Fully Verified در تعریف سخت گیرانه | B14: ۰ Measure | C14: تعریف Source to Value داخل همین فایل | D14: این صفر به معنی بی اعتبار بودن Measureها نیست؛ یعنی داده خام per firm همه Measureهای غیر Turnover داخل v35 تعبیه نشده بود | E14: Verified Measures | F14: تعریف سخت گیرانه ممیزی مستقل | G14: محتاطانه | H14: برای Fully Verified باید Raw Per Firm همه Measureها در Master وارد شود
A15: Verified With Limitation | B15: ۸ Measure | C15: S1A, V1, VAR10, IRN01, IRN02, ROB_LEGAL, ROB_NEW, ROB_STABILITY | D15: این Measureها از ممیزی عبور کرده اند ولی محدودیت روش شناختی یا داده ای دارند | E15: Verified Measures | F15: طبقه VERIFIED_WITH_LIMITATION | G15: قابل استفاده با محدودیت | H15: محدودیت هر Measure حفظ شود
A16: گپ های باز مهم | B16: Source Review | C16: وتجارت، وپاسار، حکشتی؛ تعارض CR1A فملی؛ موارد کمیته حسابرسی و منابع از مراحل قبل | D16: برای سه شرکت سندی که امکان بسته شدن کامل پرونده را بدهد دریافت نشد؛ سرنخ های تازه ثبت شد و هیچ داده حدسی وارد نشد. | E16: Gap Review v39؛ CR1A v39؛ گپ های باز | F16: ثبت تعارض بدون حدس عددی | G16: باز | H16: تکمیل اسناد تاریخی و حل تعارض ها پیش از نهایی کردن پایگاه
A19: وضعیت پروژه
A20: [x] | B20: Phase 4.2A تا Phase 4.2K
A21: [x] | B21: شش Batch تکمیل Turnover
A22: [x] | B22: ممیزی مستقل v35
A23: [x] | B23: اصلاحات تاییدشده v36
A24: [x] | B24: کشف Measureهای جدید
A25: [ ] | B25: بازبینی Source Reviewهای باز
A26: [ ] | B26: بررسی استاد
A27: [ ] | B27: Phase 5 طراحی نمونه اصلی
A28: [ ] | B28: Phase 6 استخراج در مقیاس بزرگ
A29: [ ] | B29: Phase 7 ساخت شاخص نهایی
A30: [ ] | B30: Phase 8 اعتبارسنجی
A31: [ ] | B31: Phase 9 سنجش تاب آوری

Sheet جدول استاد
A1: جدول نهایی Measureها برای ارائه به استاد پس از ممیزی مستقل
A2: Measureهای موجود، نقش نهایی، پوشش ممیزی و Candidate جدید قابل توسعه
A3: کد | B3: معیار | C3: سازه | D3: دارای داده | E3: واجد شرایط | F3: پوشش واجد شرایط | G3: پوشش کل ۳۰ | H3: Variation | I3: Evidence Quality | J3: Directionality | K3: نقش در معماری | L3: وضعیت نهایی | M3: محدودیت اصلی | N3: روش محاسبه یا تعریف عملیاتی | O3: منبع اصلی | P3: وضعیت ممیزی | Q3: اقدام
A4: S1A | B4: پروکسی استقلال ساختاری هیئت مدیره | C4: استقلال ساختاری | D4: 28 | E4: 30 | F4: =D4/E4 -> 0.93333333 | G4: =D4/30 -> 0.93333333 | H4: بله | I4: MODERATE | J4: CONTEXT_DEPENDENT | K4: اصلی | L4: SCALE_UP_PRIMARY | M4: پروکسی است نه استقلال صریح | N4: اعضای غیرموظف تقسیم بر اعضای دارای وضعیت موظف یا غیرموظف قابل تایید | O4: v22 Canonical Board Members + Source_IDهای ممیزی | P4: VERIFIED_WITH_LIMITATION | Q4: حفظ
A5: V1 | B5: تنوع رشته تحصیلی | C5: تنوع تحصیلی | D5: 28 | E5: 30 | F5: =D5/E5 -> 0.93333333 | G5: =D5/30 -> 0.93333333 | H5: بله | I5: MODERATE | J5: POSITIVE_DIRECTION | K5: اصلی | L5: SCALE_UP_PRIMARY | M5: حساس به اندازه هیئت | N5: Blau خام برابر ۱ منهای مجموع مربع سهم رشته ها | O5: v22 Education_Field_Harmonized | P5: VERIFIED_WITH_LIMITATION | Q5: حفظ
A6: VAR06_Strict | B6: تنوع سابقه حرفه ای، نسخه سخت گیرانه | C6: تنوع حرفه ای | D6: 27 | E6: 28 | F6: =D6/E6 -> 0.96428571 | G6: =D6/30 -> 0.9 | H6: بله | I6: MODERATE | J6: POSITIVE_DIRECTION | K6: اصلی با محدودیت | L6: SCALE_UP_WITH_LIMITATION | M6: بار قضاوت انسانی و پوشش ۲۷ | N6: کدگذاری Strict سپس Blau خام | O6: v25 Professional Background Strict | P6: NEEDS_CORRECTION | Q6: پوشش اصلاح شده، منطق حفظ
A7: VAR10 | B7: تخصص مالی مستند ترکیبی | C7: تخصص هیئت مدیره | D7: 28 | E7: 28 | F7: =D7/E7 -> 1 | G7: =D7/30 -> 0.93333333 | H7: بله | I7: MODERATE | J7: POSITIVE_DIRECTION | K7: اصلی با محدودیت | L7: SCALE_UP_WITH_LIMITATION | M7: همپوشانی با سابقه حرفه ای و تحصیلی | N7: اعضای دارای تخصص مالی مستند تقسیم بر اعضای قابل ارزیابی | O7: v25 Financial Expertise | P7: VERIFIED_WITH_LIMITATION | Q7: حفظ
A8: CR1A | B8: تغییر رئیس هیئت مدیره | C8: ثبات رهبری | D8: ='CR1A v39'!B39 -> 26 | E8: ='CR1A v39'!B44 -> 30 | F8: =D8/E8 -> 0.86666667 | G8: =D8/30 -> 0.86666667 | H8: بله | I8: LOW | J8: NO_CLEAR_DIRECTION | K8: کنترلی | L8: CONTROL_DIAGNOSTIC | M8: ۲۷ کد موجود؛ ۲۶ بدون تعارض باز ثبت شده؛ فملی نیازمند بررسی و سه شرکت نامشخص | N8: مقایسه هویت رئیس در chronology رسمی | O8: CR1A v39؛ بازسازی سطح کرسی v38 و ممیزی های قبلی | P8: NEEDS_SOURCE_REVIEW | Q8: خارج Composite
A9: AUD01 | B9: وجود کمیته حسابرسی | C9: نظارت | D9: 29 | E9: 30 | F9: =D9/E9 -> 0.96666667 | G9: =D9/30 -> 0.96666667 | H9: بله | I9: MODERATE | J9: POSITIVE_DIRECTION | K9: اصلی با محدودیت | L9: SCALE_UP_WITH_LIMITATION | M9: وپاسار هنوز بدون افشای صریح؛ مقطع پایان دوره شرکت ها یکسان نیست | N9: وجود فقط با افشای رسمی صریح تایید می شود | O9: AC Company v40 و AC Sources v40 | P9: VERIFIED_WITH_LIMITATION | Q9: حفظ با بازبینی موارد باز
A10: AUD02 | B10: اندازه کمیته حسابرسی | C10: نظارت | D10: 27 | E10: 30 | F10: =D10/E10 -> 0.9 | G10: =D10/30 -> 0.9 | H10: بله | I10: LOW | J10: NONLINEAR_POSSIBLE | K10: Robustness | L10: ROBUSTNESS_ONLY | M10: سه شرکت با فهرست ناقص یا نامشخص (فخوز، حکشتی، وپاسار) | N10: تعداد اعضای کمیته در roster کامل و قابل خواندن | O10: AC Members v40 و AC Company v40 | P10: VERIFIED_WITH_LIMITATION | Q10: فقط Robustness
A11: IRN01 | B11: سهم کرسی اشخاص حقوقی | C11: ساختار نمایندگی | D11: 29 | E11: 30 | F11: =D11/E11 -> 0.96666667 | G11: =D11/30 -> 0.96666667 | H11: ضعیف | I11: MODERATE | J11: NO_CLEAR_DIRECTION | K11: ساختاری | L11: STRUCTURAL_GOVERNANCE_MEASURE | M11: تقریبا Dummy بانکی | N11: کرسی حقوقی تقسیم بر کل کرسی های فعال قابل طبقه بندی | O11: v22 Legal_Entity_Represented | P11: VERIFIED_WITH_LIMITATION | Q11: حفظ به عنوان ساختاری
A12: IRN02 | B12: سهم کرسی اشخاص حقیقی | C12: ساختار نمایندگی | D12: 29 | E12: 30 | F12: =D12/E12 -> 0.96666667 | G12: =D12/30 -> 0.96666667 | H12: ضعیف | I12: MODERATE | J12: NO_CLEAR_DIRECTION | K12: Robustness | L12: ROBUSTNESS_ONLY | M12: مکمل دقیق IRN01 | N12: کرسی حقیقی تقسیم بر کل کرسی های فعال قابل طبقه بندی | O12: v22 | P12: VERIFIED_WITH_LIMITATION | Q12: همزمان با IRN01 وارد نشود
